<?xml version="1.0"?>
<robot xmlns:xacro="http://www.ros.org/wiki/xacro">

  <!-- link 1 -->
  <link name="link1">
    <visual>
      <origin xyz="0 0 0" rpy="0 0 0"/>
      <geometry>
        <mesh filename="package://open_manipulator_p_description/meshes/link1.stl" scale="0.001 0.001 0.001"/>
      </geometry>
      <material name="grey"/>
    </visual>

    <collision>
      <origin xyz="0 0 0" rpy="0 0 0"/>
      <geometry>
        <mesh filename="package://open_manipulator_p_description/meshes/link1.stl" scale="0.001 0.001 0.001"/>
      </geometry>
    </collision>

    <inertial>
      <origin xyz="0.0000000e+00 -1.7653633e-04 -1.0030209e-03" rpy="0 0 0"/>
      <mass value="9.4360595e-01"/>
      <inertia ixx="1.0e-03" ixy="0.0" ixz="0.0" 
               iyx="0.0" iyy="1.0e-03" iyz="0.0" 
               izx="0.0" izy="0.0" izz="1.0e-03" />
    </inertial>
  </link>

  <!-- Joint 1 -->
  <joint name="joint1" type="revolute">
    <parent link="link1"/>
    <child link="link2"/>
    <origin xyz="0.0 0.0 0.126" rpy="0 0 0"/>
    <axis xyz="0 0 1"/>
    <limit velocity="6.5" effort="1000" lower="${-pi*0.5}" upper="${pi*0.5}" />
    <dynamics damping="0.7"/>
  </joint>

  <!-- link 2 -->
  <link name="link2">
    <visual>
      <origin xyz="0 0 0" rpy="0 0 0"/>
      <geometry>
        <mesh filename="package://open_manipulator_p_description/meshes/link2.stl" scale="0.001 0.001 0.001"/>
      </geometry>
      <material name="grey"/>
    </visual>

    <collision>
      <origin xyz="0 0 0" rpy="0 0 0"/>
      <geometry>
        <mesh filename="package://open_manipulator_p_description/meshes/link2.stl" scale="0.001 0.001 0.001"/>
      </geometry>
    </collision>
    
    <inertial>
      <origin xyz="0.0000000e+00 -1.7653633e-04 -1.0030209e-03" rpy="0 0 0"/>
      <mass value="9.4360595e-01"/>
      <inertia ixx="1.5694005e-03" ixy="0.0" ixz="0.0" 
               iyx="0.0" iyy="4.5593385e-04" iyz="6.4581824e-09" 
               izx="0.0" izy="6.4581824e-09" izz="1.5561809e-03" />
    </inertial>
  </link>

  <!-- Joint 2 -->
  <joint name="joint2" type="revolute">
    <parent link="link2"/>
    <child link="link3"/>
    <origin xyz="0.0 0.069 0.033" rpy="0 0 0"/>
    <axis xyz="0 1 0"/>
    <limit velocity="6.5" effort="1000" lower="${-pi*0.5}" upper="${pi*0.5}" />
    <dynamics damping="0.7"/>
  </joint>

  <!-- link 3 -->
  <link name="link3">
    <visual>
      <origin xyz="0 0 0" rpy="0 0 0"/>
      <geometry>
        <mesh filename="package://open_manipulator_p_description/meshes/link3.stl" scale="0.001 0.001 0.001"/>
      </geometry>
      <material name="grey"/>
    </visual>

    <collision>
      <origin xyz="0 0 0" rpy="0 0 0"/>
      <geometry>
        <mesh filename="package://open_manipulator_p_description/meshes/link3.stl" scale="0.001 0.001 0.001"/>
      </geometry>
    </collision>

    <inertial>
      <origin xyz="1.5751501e-02 -2.2073221e-04 1.9913687e-01" rpy="0 0 0"/>
      <mass value="1.3825862e+00"/>
      <inertia ixx="6.7630430e-02" ixy="-1.9988597e-05" ixz="-5.7477571e-03" 
               iyx="-1.9988597e-05" iyy="6.7208001e-02" iyz="7.4823203e-05" 
               izx="-5.7477571e-03" izy="7.4823203e-05" izz="2.6031353e-03" />
    </inertial>
  </link>

  <!-- Joint 3 -->
  <joint name="joint3" type="revolute">
    <parent link="link3"/>
    <child link="link4"/>
    <origin xyz="0.03000 -0.01150 0.26400" rpy="0 0 0"/>
    <axis xyz="0 1 0"/>
    <limit velocity="6.5" effort="1000" lower="${-pi*0.5}" upper="${pi*0.5}" />
    <dynamics damping="0.7"/>
  </joint>

  <!-- link 4 -->
  <link name="link4">
    <visual>
      <origin xyz="0 0 0" rpy="0 0 0"/>
      <geometry>
        <mesh filename="package://open_manipulator_p_description/meshes/link4.stl" scale="0.001 0.001 0.001"/>
      </geometry>
      <material name="grey"/>
    </visual>

    <collision>
      <origin xyz="0 0 0" rpy="0 0 0"/>
      <geometry>
        <mesh filename="package://open_manipulator_p_description/meshes/link4.stl" scale="0.001 0.001 0.001"/>
      </geometry>
    </collision>

    <inertial>
      <origin xyz="3.0352597e-04 4.1703880e-05 3.8074728e-01" rpy="0 0 0"/>
      <mass value="1.2126965e+00"/>
      <inertia ixx="1.7985424e-01" ixy="-9.9417476e-07" ixz="-8.1564441e-05" 
               iyx="-9.9417476e-07" iyy="1.7948679e-01" iyz="-1.7705853e-05" 
               izx="-8.1564441e-05" izy="-1.7705853e-05" izz="1.1422079e-03" />
    </inertial>
  </link>

  <!-- Joint 4 -->
  <joint name="joint4" type="revolute">
    <parent link="link4"/>
    <child link="link5"/>
    <origin xyz="0.19500 -0.05750 0.03000" rpy="0 0 0"/>
    <axis xyz="1 0 0"/>
    <limit velocity="6.5" effort="1000" lower="${-pi*0.5}" upper="${pi*0.5}" />
    <dynamics damping="0.7"/>
  </joint>

  <!-- link 5 -->
  <link name="link5">
    <visual>
      <origin xyz="0 0 0" rpy="0 0 0"/>
      <geometry>
        <mesh filename="package://open_manipulator_p_description/meshes/link5.stl" scale="0.001 0.001 0.001"/>
      </geometry>
      <material name="grey"/>
    </visual>

    <collision>
      <origin xyz="0 0 0" rpy="0 0 0"/>
      <geometry>
        <mesh filename="package://open_manipulator_p_description/meshes/link5.stl" scale="0.001 0.001 0.001"/>
      </geometry>
    </collision>

    <inertial>
      <origin xyz="-2.1388493e-06 -2.2290515e-03 5.1387207e-01" rpy="0 0 0"/>
      <mass value="4.6635550e-01"/>
      <inertia ixx="1.2357713e-01" ixy="-1.9465317e-09" ixz="5.1228604e-07" 
               iyx="-1.9465317e-09" iyy="1.2339567e-01" iyz="5.3769657e-04" 
               izx="5.1228604e-07" izy="5.3769657e-04" izz="3.3216863e-04" />
    </inertial>
  </link>

  <!-- Joint 5 -->
  <joint name="joint5" type="revolute">
    <parent link="link5"/>
    <child link="link6"/>
    <origin xyz="0.06300 0.04500 0.00000" rpy="0 0 0"/>
    <axis xyz="0 1 0"/>
    <limit velocity="6.5" effort="1000" lower="${-pi*0.5}" upper="${pi*0.5}" />
    <dynamics damping="0.7"/>
  </joint>

  <!-- link 6 -->
  <link name="link6">
    <visual>
      <origin xyz="0 0 0" rpy="0 0 0"/>
      <geometry>
        <mesh filename="package://open_manipulator_p_description/meshes/link6.stl" scale="0.001 0.001 0.001"/>
      </geometry>
      <material name="grey"/>
    </visual>

    <collision>
      <origin xyz="0 0 0" rpy="0 0 0"/>
      <geometry>
        <mesh filename="package://open_manipulator_p_description/meshes/link6.stl" scale="0.001 0.001 0.001"/>
      </geometry>
    </collision>

    <inertial>
      <origin xyz="-2.1268822e-06 1.8039922e-04 5.9028250e-01" rpy="0 0 0"/>
      <mass value="4.2561606e-01"/>
      <inertia ixx="1.4881319e-01" ixy="0.0000000e+00" ixz="5.3435266e-07" 
               iyx="0.0000000e+00" iyy="1.4872708e-01" iyz="-4.3708754e-05" 
               izx="5.3435266e-07" izy="-4.3708754e-05" izz="2.1040082e-04" />
    </inertial>
  </link>

  <!-- Joint 6 -->
  <joint name="joint6" type="revolute">
    <parent link="link6"/>
    <child link="end_link"/>
    <origin xyz="0.12300 -0.04500 0.00000" rpy="0 0 0"/>
    <axis xyz="1 0 0"/>
    <limit velocity="6.5" effort="1000" lower="${-pi*0.5}" upper="${pi*0.5}" />
    <dynamics damping="0.7"/>
  </joint>

  <!-- end link -->
  <link name="end_link">
    <visual>
      <origin xyz="0.0 0.0 0.0" rpy="0 0 0" />
      <geometry>
        <mesh filename="package://open_manipulator_p_description/meshes/end_link.stl" scale="0.001 0.001 0.001"/>
      </geometry>
      <material name="grey"/>
    </visual>

    <collision>
      <origin xyz="0.0 0.0 0.0" rpy="0 0 0" />
      <geometry>
        <mesh filename="package://open_manipulator_p_description/meshes/end_link.stl" scale="0.001 0.001 0.001"/>
      </geometry>
    </collision>

    <inertial>
      <origin xyz="0.00337 0.00000 0.00000" rpy="0 0 0"/>
      <mass value="0.01919"/>
      <inertia ixx="1.25e-4" ixy="0.0" ixz="0.0" iyy="1.25e-4" iyz="0.0" izz="1.25e-4" />
    </inertial>
  </link>

</robot>
